<?xml version="1.0" ?>
<!-- =================================================================================== -->
<!-- |    This document was autogenerated by xacro from my_robot_integration.urdf.xacro | -->
<!-- |    EDITING THIS FILE BY HAND IS NOT RECOMMENDED                                 | -->
<!-- =================================================================================== -->
<!-- Name your robot here -->
<robot name="skateboard">
  <link name="base_link">
    <inertial>
      <origin rpy="0 0 0" xyz="-0.00458216531210875 8.24703628388157E-07 0.293836175998977"/>
      <mass value="46.6638789557158"/>
      <inertia ixx="0.974368837581962" ixy="8.66048070135966E-06" ixz="-0.00163912437239369" iyy="3.40173203153984" iyz="1.79342534681446E-06" izz="4.29781608665177"/>
    </inertial>
    <visual>
      <origin rpy="0 0 0" xyz="0 0 0"/>
      <geometry>
        <mesh filename="package://skateboard/meshes/base_link.STL"/>
      </geometry>
      <material name="">
        <color rgba="0.792156862745098 0.819607843137255 0.933333333333333 1"/>
      </material>
    </visual>
    <collision>
      <origin rpy="0 0 0" xyz="0 0 0"/>
      <geometry>
        <mesh filename="package://skateboard/meshes/base_link.STL"/>
      </geometry>
    </collision>
  </link>
  <link name="front_left_castor">
    <inertial>
      <origin rpy="0 0 0" xyz="0.0134807351662773 0.1061390440721 -0.0635"/>
      <mass value="0.375748041819476"/>
      <inertia ixx="0.00186061964746791" ixy="-0.000120223941784029" ixz="-1.9874701838698E-22" iyy="0.00087989031280542" iyz="2.67789108792648E-19" izz="0.00141382013714359"/>
    </inertial>
    <visual>
      <origin rpy="0 0 0" xyz="0 0 0"/>
      <geometry>
        <mesh filename="package://skateboard/meshes/front_left_castor.STL"/>
      </geometry>
      <material name="">
        <color rgba="0.792156862745098 0.819607843137255 0.933333333333333 1"/>
      </material>
    </visual>
    <collision>
      <origin rpy="0 0 0" xyz="0 0 0"/>
      <geometry>
        <mesh filename="package://skateboard/meshes/front_left_castor.STL"/>
      </geometry>
    </collision>
  </link>
  <joint name="front_left_castor_joint" type="revolute">
    <origin rpy="1.5708 0 3.1416" xyz="0.28412 0.2286 0.10465"/>
    <parent link="base_link"/>
    <child link="front_left_castor"/>
    <axis xyz="0 0 1"/>
    <limit effort="0" lower="0" upper="0" velocity="0"/>
  </joint>
  <link name="front_left_shaft">
    <inertial>
      <origin rpy="0 0 0" xyz="0 0 -0.0635"/>
      <mass value="0.0858595098594949"/>
      <inertia ixx="0.0001009908613904" ixy="2.99244959851748E-38" ixz="-1.26927539495442E-38" iyy="0.0001009908613904" iyz="3.2318755504395E-21" izz="9.64668125467686E-06"/>
    </inertial>
    <visual>
      <origin rpy="0 0 0" xyz="0 0 0"/>
      <geometry>
        <mesh filename="package://skateboard/meshes/front_left_shaft.STL"/>
      </geometry>
      <material name="">
        <color rgba="0.792156862745098 0.819607843137255 0.933333333333333 1"/>
      </material>
    </visual>
    <collision>
      <origin rpy="0 0 0" xyz="0 0 0"/>
      <geometry>
        <mesh filename="package://skateboard/meshes/front_left_shaft.STL"/>
      </geometry>
    </collision>
  </link>
  <joint name="front_left_shaft_joint" type="continuous">
    <origin rpy="0 0 0" xyz="0 0 0"/>
    <parent link="front_left_castor"/>
    <child link="front_left_shaft"/>
    <axis xyz="0 0 1"/>
  </joint>
  <link name="front_left_wheel">
    <inertial>
      <origin rpy="0 0 0" xyz="1.01629056954433E-05 0.000757681850388048 -0.0634999999999999"/>
      <mass value="1.55942631528513"/>
      <inertia ixx="0.00546334240124887" ixy="4.47252015876343E-10" ixz="-1.97875367151852E-19" iyy="0.00546337573952603" iyz="-6.88313983385968E-20" izz="0.00981623598058744"/>
    </inertial>
    <visual>
      <origin rpy="0 0 0" xyz="0 0 0"/>
      <geometry>
        <mesh filename="package://skateboard/meshes/front_left_wheel.STL"/>
      </geometry>
      <material name="">
        <color rgba="0.792156862745098 0.819607843137255 0.933333333333333 1"/>
      </material>
    </visual>
    <collision>
      <origin rpy="0 0 0" xyz="0 0 0"/>
      <geometry>
        <mesh filename="package://skateboard/meshes/front_left_wheel.STL"/>
      </geometry>
    </collision>
  </link>
  <joint name="front_left_wheel_joint" type="fixed">
    <origin rpy="0 0 0" xyz="0 0 0"/>
    <parent link="front_left_shaft"/>
    <child link="front_left_wheel"/>
    <axis xyz="0 0 0"/>
  </joint>
  <link name="front_right_castor">
    <inertial>
      <origin rpy="0 0 0" xyz="0.0134807351662771 0.1061390440721 0.0634999999999999"/>
      <mass value="0.375748041819476"/>
      <inertia ixx="0.00186061964746791" ixy="-0.000120223941784028" ixz="1.0045810754436E-18" iyy="0.000879890312805418" iyz="-5.34477789717464E-19" izz="0.00141382013714358"/>
    </inertial>
    <visual>
      <origin rpy="0 0 0" xyz="0 0 0"/>
      <geometry>
        <mesh filename="package://skateboard/meshes/front_right_castor.STL"/>
      </geometry>
      <material name="">
        <color rgba="0.792156862745098 0.819607843137255 0.933333333333333 1"/>
      </material>
    </visual>
    <collision>
      <origin rpy="0 0 0" xyz="0 0 0"/>
      <geometry>
        <mesh filename="package://skateboard/meshes/front_right_castor.STL"/>
      </geometry>
    </collision>
  </link>
  <joint name="front_right_castor_joint" type="revolute">
    <origin rpy="1.5708 0 3.123" xyz="0.28293 -0.22892 0.10465"/>
    <parent link="base_link"/>
    <child link="front_right_castor"/>
    <axis xyz="0 0 -1"/>
    <limit effort="0" lower="0" upper="0" velocity="0"/>
  </joint>
  <link name="front_right_shaft">
    <inertial>
      <origin rpy="0 0 0" xyz="-2.22044604925031E-16 0 0.0635000000000001"/>
      <mass value="0.0858595098594949"/>
      <inertia ixx="0.0001009908613904" ixy="2.7662421850965E-23" ixz="-2.40874994375442E-21" iyy="0.0001009908613904" iyz="3.94898122378413E-21" izz="9.64668125467686E-06"/>
    </inertial>
    <visual>
      <origin rpy="0 0 0" xyz="0 0 0"/>
      <geometry>
        <mesh filename="package://skateboard/meshes/front_right_shaft.STL"/>
      </geometry>
      <material name="">
        <color rgba="0.792156862745098 0.819607843137255 0.933333333333333 1"/>
      </material>
    </visual>
    <collision>
      <origin rpy="0 0 0" xyz="0 0 0"/>
      <geometry>
        <mesh filename="package://skateboard/meshes/front_right_shaft.STL"/>
      </geometry>
    </collision>
  </link>
  <joint name="front_right_shaft_joint" type="continuous">
    <origin rpy="0 0 0" xyz="0 0 0"/>
    <parent link="front_right_castor"/>
    <child link="front_right_shaft"/>
    <axis xyz="0 0 -1"/>
  </joint>
  <link name="front_right_wheel">
    <inertial>
      <origin rpy="0 0 0" xyz="1.01629056949992E-05 0.000757681850388048 0.0635"/>
      <mass value="1.55942631528513"/>
      <inertia ixx="0.00546334240124888" ixy="4.47252014931879E-10" ixz="-2.03287907341032E-20" iyy="0.00546337573952603" iyz="-4.6342149199017E-20" izz="0.00981623598058744"/>
    </inertial>
    <visual>
      <origin rpy="0 0 0" xyz="0 0 0"/>
      <geometry>
        <mesh filename="package://skateboard/meshes/front_right_wheel.STL"/>
      </geometry>
      <material name="">
        <color rgba="0.792156862745098 0.819607843137255 0.933333333333333 1"/>
      </material>
    </visual>
    <collision>
      <origin rpy="0 0 0" xyz="0 0 0"/>
      <geometry>
        <mesh filename="package://skateboard/meshes/front_right_wheel.STL"/>
      </geometry>
    </collision>
  </link>
  <joint name="front_right_wheel_joint" type="fixed">
    <origin rpy="0 0 0" xyz="0 0 0"/>
    <parent link="front_right_shaft"/>
    <child link="front_right_wheel"/>
    <axis xyz="0 0 0"/>
  </joint>
  <link name="rear_left_castor">
    <inertial>
      <origin rpy="0 0 0" xyz="3.33066907387547E-16 0.121707358571448 -0.06858"/>
      <mass value="0.366948048129126"/>
      <inertia ixx="0.000748556266523244" ixy="-1.01060150672454E-19" ixz="1.31376525772936E-19" iyy="0.000740864473475818" iyz="8.44762671544618E-20" izz="0.000632863553143694"/>
    </inertial>
    <visual>
      <origin rpy="0 0 0" xyz="0 0 0"/>
      <geometry>
        <mesh filename="package://skateboard/meshes/rear_left_castor.STL"/>
      </geometry>
      <material name="">
        <color rgba="0.792156862745098 0.819607843137255 0.933333333333333 1"/>
      </material>
    </visual>
    <collision>
      <origin rpy="0 0 0" xyz="0 0 0"/>
      <geometry>
        <mesh filename="package://skateboard/meshes/rear_left_castor.STL"/>
      </geometry>
    </collision>
  </link>
  <joint name="rear_left_castor_joint" type="fixed">
    <origin rpy="1.5708 0 -3.1416" xyz="-0.24166 0.20828 0.10478"/>
    <parent link="base_link"/>
    <child link="rear_left_castor"/>
    <axis xyz="0 0 0"/>
  </joint>
  <link name="rear_left_shaft">
    <inertial>
      <origin rpy="0 0 0" xyz="-1.11022302462516E-16 1.11022302462516E-16 -0.0685799999999998"/>
      <mass value="0.0679514721041126"/>
      <inertia ixx="5.51726293118822E-05" ixy="2.58732738125917E-22" ixz="6.57806775316306E-21" iyy="5.51726293118822E-05" iyz="9.63988248762429E-21" izz="7.75429241942671E-06"/>
    </inertial>
    <visual>
      <origin rpy="0 0 0" xyz="0 0 0"/>
      <geometry>
        <mesh filename="package://skateboard/meshes/rear_left_shaft.STL"/>
      </geometry>
      <material name="">
        <color rgba="0.792156862745098 0.819607843137255 0.933333333333333 1"/>
      </material>
    </visual>
    <collision>
      <origin rpy="0 0 0" xyz="0 0 0"/>
      <geometry>
        <mesh filename="package://skateboard/meshes/rear_left_shaft.STL"/>
      </geometry>
    </collision>
  </link>
  <joint name="rear_left_shaft_joint" type="continuous">
    <origin rpy="0 0 0" xyz="0 0 0"/>
    <parent link="rear_left_castor"/>
    <child link="rear_left_shaft"/>
    <axis xyz="0 0 -1"/>
  </joint>
  <link name="rear_left_wheel">
    <inertial>
      <origin rpy="0 0 0" xyz="9.36913719650212E-05 0.000751935501142831 -0.06858"/>
      <mass value="1.55942631528513"/>
      <inertia ixx="0.00546334290510486" ixy="4.09192546748377E-09" ixz="-2.12443650692712E-19" iyy="0.00546337523567005" iyz="-1.67504107850689E-19" izz="0.00981623598058744"/>
    </inertial>
    <visual>
      <origin rpy="0 0 0" xyz="0 0 0"/>
      <geometry>
        <mesh filename="package://skateboard/meshes/rear_left_wheel.STL"/>
      </geometry>
      <material name="">
        <color rgba="0.792156862745098 0.819607843137255 0.933333333333333 1"/>
      </material>
    </visual>
    <collision>
      <origin rpy="0 0 0" xyz="0 0 0"/>
      <geometry>
        <mesh filename="package://skateboard/meshes/rear_left_wheel.STL"/>
      </geometry>
    </collision>
  </link>
  <joint name="rear_left_wheel_joint" type="fixed">
    <origin rpy="0 0 0" xyz="0 0 0"/>
    <parent link="rear_left_shaft"/>
    <child link="rear_left_wheel"/>
    <axis xyz="0 0 0"/>
  </joint>
  <link name="rear_right_castor">
    <inertial>
      <origin rpy="0 0 0" xyz="1.11022302462516E-16 0.121707358571448 0.0685799999999999"/>
      <mass value="0.366948048129126"/>
      <inertia ixx="0.000748556266523244" ixy="-2.8369927385419E-20" ixz="5.613315174775E-20" iyy="0.000740864473475818" iyz="5.28772548313157E-20" izz="0.000632863553143694"/>
    </inertial>
    <visual>
      <origin rpy="0 0 0" xyz="0 0 0"/>
      <geometry>
        <mesh filename="package://skateboard/meshes/rear_right_castor.STL"/>
      </geometry>
      <material name="">
        <color rgba="0.792156862745098 0.819607843137255 0.933333333333333 1"/>
      </material>
    </visual>
    <collision>
      <origin rpy="0 0 0" xyz="0 0 0"/>
      <geometry>
        <mesh filename="package://skateboard/meshes/rear_right_castor.STL"/>
      </geometry>
    </collision>
  </link>
  <joint name="rear_right_castor_joint" type="fixed">
    <origin rpy="1.5708 0 3.1416" xyz="-0.24166 -0.20828 0.10478"/>
    <parent link="base_link"/>
    <child link="rear_right_castor"/>
    <axis xyz="0 0 0"/>
  </joint>
  <link name="rear_right_shaft">
    <inertial>
      <origin rpy="0 0 0" xyz="1.11022302462516E-16 -1.11022302462516E-16 0.06858"/>
      <mass value="0.0679514721041126"/>
      <inertia ixx="5.51726293118822E-05" ixy="2.79660407623497E-22" ixz="-2.38144420119797E-20" iyy="5.51726293118822E-05" iyz="-9.25284210881679E-22" izz="7.7542924194267E-06"/>
    </inertial>
    <visual>
      <origin rpy="0 0 0" xyz="0 0 0"/>
      <geometry>
        <mesh filename="package://skateboard/meshes/rear_right_shaft.STL"/>
      </geometry>
      <material name="">
        <color rgba="0.792156862745098 0.819607843137255 0.933333333333333 1"/>
      </material>
    </visual>
    <collision>
      <origin rpy="0 0 0" xyz="0 0 0"/>
      <geometry>
        <mesh filename="package://skateboard/meshes/rear_right_shaft.STL"/>
      </geometry>
    </collision>
  </link>
  <joint name="rear_right_shaft_joint" type="continuous">
    <origin rpy="0 0 0" xyz="0 0 0"/>
    <parent link="rear_right_castor"/>
    <child link="rear_right_shaft"/>
    <axis xyz="0 0 -1"/>
  </joint>
  <link name="rear_right_wheel">
    <inertial>
      <origin rpy="0 0 0" xyz="9.36913719651322E-05 0.000751935501142831 0.06858"/>
      <mass value="1.55942631528513"/>
      <inertia ixx="0.00546334290510487" ixy="4.09192546791387E-09" ixz="1.27619464698766E-18" iyy="0.00546337523567006" iyz="-5.60649921346398E-20" izz="0.00981623598058745"/>
    </inertial>
    <visual>
      <origin rpy="0 0 0" xyz="0 0 0"/>
      <geometry>
        <mesh filename="package://skateboard/meshes/rear_right_wheel.STL"/>
      </geometry>
      <material name="">
        <color rgba="0.792156862745098 0.819607843137255 0.933333333333333 1"/>
      </material>
    </visual>
    <collision>
      <origin rpy="0 0 0" xyz="0 0 0"/>
      <geometry>
        <mesh filename="package://skateboard/meshes/rear_right_wheel.STL"/>
      </geometry>
    </collision>
  </link>
  <joint name="rear_right_wheel_joint" type="fixed">
    <origin rpy="0 0 0" xyz="0 0 0"/>
    <parent link="rear_right_shaft"/>
    <child link="rear_right_wheel"/>
    <axis xyz="0 0 0"/>
  </joint>
  <link name="dummy_link"/>
  <joint name="dummy_joint" type="fixed">
    <parent link="dummy_link"/>
    <child link="base_link"/>
    <origin rpy="0 0 0" xyz="0 0 0"/>
    <axis xyz="0 0 0"/>
  </joint>
  <link name="base_laser">
    <inertial>
      <origin rpy="0 0 0" xyz="-0.00029774 0.0066667 0.00013047"/>
      <mass value="0.15717"/>
      <inertia ixx="6.7885E-05" ixy="-1.3987E-07" ixz="-8.1554E-07" iyy="0.00013173" iyz="-9.0932E-08" izz="7.1972E-05"/>
    </inertial>
    <visual>
      <origin rpy="0 0 0" xyz="0 0 0"/>
      <geometry>
        <mesh filename="package://ydlidar_ros/meshes/ydlidar.dae"/>
      </geometry>
      <material name="">
        <color rgba="0.64706 0.61961 0.58824 1"/>
      </material>
    </visual>
    <collision>
      <origin rpy="0 0 0" xyz="0 0 0"/>
      <geometry>
        <mesh filename="package://ydlidar_ros/meshes/ydlidar.dae"/>
      </geometry>
    </collision>
  </link>
  <link name="laser_frame">
    <inertial>
      <origin rpy="0 0 0" xyz="-0.00036659 0.00064155 -0.00027052"/>
      <mass value="0.25482"/>
      <inertia ixx="8.9194E-05" ixy="1.8116E-07" ixz="3.6435E-08" iyy="0.00018279" iyz="2.423E-07" izz="0.00011103"/>
    </inertial>
    <visual>
      <origin
        xyz="0 0 0"
        rpy="0 0 0" />
      <geometry>
        <mesh
          filename="package://ydlidar_ros/meshes/ydlidar.dae" />
      </geometry>
      <material
        name="">
        <color
          rgba="0.64706 0.61961 0.58824 1" />
      </material>
    </visual>
    <collision>
      <origin
        xyz="0 0 0"
        rpy="0 0 0" />
      <geometry>
        <mesh
          filename="package://ydlidar_ros/meshes/ydlidar.dae" />
      </geometry>
    </collision>
  </link>
  <joint name="laser_joint" type="fixed">
    <origin rpy="0 0 0" xyz="0 0 0.03172"/>
    <parent link="base_laser"/>
    <child link="laser_frame"/>
    <axis xyz="0 0 0"/>
  </joint>
  <!-- Add your gazebo sensors here -->
  <gazebo reference="base_laser">
    <!-- <gravity>true</gravity> -->
    <!-- Gazebo has fixed set of Sensors types. Check them out here <> -->
    <sensor name="laser" type="ray">
      <!-- Add in your sensor characteristics -->
      <pose> 0 0 0 0 0 0 </pose>
      <visualise>true</visualise>
      <update_rate>40</update_rate>
      <!-- <always_on>true</always_on> -->
      <ray>
        <scan>
          <horizontal>
            <samples>720</samples>
            <resolution>1</resolution>
            <min_angle>-1.570796</min_angle>
            <max_angle>1.570796</max_angle>
          </horizontal>
        </scan>
        <range>
          <min>0.10</min>
          <max>30.0</max>
          <resolution>0.01</resolution>
        </range>
        <noise>
          <type>gaussian</type>
          <mean>0.0</mean>
          <stddev>0.01</stddev>
        </noise>
      </ray>
      <plugin filename="libgazebo_ros_laser.so" name="gazebo_ros_head_hokuyo_controller">
        <!-- Use topic name as /my_robot/scan -->
        <topicName>/skateboard/scan</topicName>
        <frameName>laser_frame</frameName>
      </plugin>
    </sensor>
  </gazebo>
  <!--  Gazebo plugin for control here is already added for you -->
  <gazebo>
    <plugin filename="libgazebo_ros_control.so" name="gazebo_ros_control">
      <robotNamespace>/skateboard</robotNamespace>
      <robotSimType>gazebo_ros_control/DefaultRobotHWSim</robotSimType>
      <legacyModeNS>true</legacyModeNS>
    </plugin>
  </gazebo>
  <!-- Create a joint between your robot and sensor -->
  <joint name="lidar_joint" type="fixed">
    <origin rpy="0 0 0" xyz="0 0 0"/>
    <parent link="base_link"/>
    <child link="base_laser"/>
    <axis xyz="0 0 0"/>
  </joint>


  <transmission name="rear_motor_left">
  <type>transmission_interface/SimpleTransmission</type>
  <joint name="rear_left_shaft_joint">
    <hardwareInterface>hardware_interface/VelocityJointInterface</hardwareInterface>
  </joint>
  <actuator name="rear_motor_left">
    <mechanicalReduction>50</mechanicalReduction>
    <hardwareInterface>hardware_interface/VelocityJointInterface</hardwareInterface>
  </actuator>
  </transmission>

  <transmission name="rear_motor_right">
  <type>transmission_interface/SimpleTransmission</type>
  <joint name="rear_right_shaft_joint">
    <hardwareInterface>hardware_interface/VelocityJointInterface</hardwareInterface>
  </joint>
  <actuator name="rear_motor_right">
    <mechanicalReduction>50</mechanicalReduction>
    <hardwareInterface>hardware_interface/VelocityJointInterface</hardwareInterface>
  </actuator>
  </transmission>

  <transmission name="left_castor_motor">
  <type>transmission_interface/SimpleTransmission</type>
  <joint name="front_left_castor_joint">
    <hardwareInterface>hardware_interface/EffortJointInterface</hardwareInterface>
  </joint>
  <actuator name="left_castor_motor">
    <mechanicalReduction>50</mechanicalReduction>
    <hardwareInterface>hardware_interface/EffortJointInterface</hardwareInterface>
  </actuator>
  </transmission>

  <transmission name="right_castor_motor">
  <type>transmission_interface/SimpleTransmission</type>
  <joint name="front_right_castor_joint">
    <hardwareInterface>hardware_interface/EffortJointInterface</hardwareInterface>
  </joint>
  <actuator name="right_castor_motor">
    <mechanicalReduction>50</mechanicalReduction>
    <hardwareInterface>hardware_interface/EffortJointInterface</hardwareInterface>
  </actuator>
  </transmission>

</robot>
